WARNING: This is a development server. Do not use it in a production deployment. Use a production WSGI server instead.
 * Running on http://127.0.0.1:5000
Press CTRL+C to quit
 * Restarting with stat
 * Debugger is active!
 * Debugger PIN: 499-259-299
Running query: SELECT * FROM friends;
[<friend.Friend object at 0x000002B0B1B98BD0>, <friend.Friend object at 0x000002B0B3579850>]
127.0.0.1 - - [09/Feb/2023 07:41:54] "GET / HTTP/1.1" 200 -
 * Detected change in 'E:\\Dojo\\Pre-Bootcamp_Public\\Pre-Bootcamp_Assignments\\python\\flask_mysql\\db_connection\\First_Flask\\mysqlconnection.py', reloading
 * Restarting with stat
 * Debugger is active!
 * Debugger PIN: 499-259-299
Running query: SELECT * FROM friends;
[<friend.Friend object at 0x00000178B307B910>, <friend.Friend object at 0x00000178B16A8BD0>]
127.0.0.1 - - [09/Feb/2023 07:43:06] "GET / HTTP/1.1" 200 -
 * Detected change in 'E:\\Dojo\\Pre-Bootcamp_Public\\Pre-Bootcamp_Assignments\\python\\flask_mysql\\db_connection\\First_Flask\\friend.py', reloading
 * Restarting with stat
 * Debugger is active!
 * Debugger PIN: 499-259-299
 * Detected change in 'E:\\Dojo\\Pre-Bootcamp_Public\\Pre-Bootcamp_Assignments\\python\\flask_mysql\\db_connection\\First_Flask\\mysqlconnection.py', reloading
 * Restarting with stat
 * Debugger is active!
 * Debugger PIN: 499-259-299
127.0.0.1 - - [09/Feb/2023 07:43:18] "GET / HTTP/1.1" 500 -
Traceback (most recent call last):
  File "C:\Users\shrad\.virtualenvs\First_Flask-Zylcdab4\Lib\site-packages\flask\app.py", line 2548, in __call__
    return self.wsgi_app(environ, start_response)
           ^^^^^^^^^^^^^^^^^^^^^^^^^^^^^^^^^^^^^^
  File "C:\Users\shrad\.virtualenvs\First_Flask-Zylcdab4\Lib\site-packages\flask\app.py", line 2528, in wsgi_app
    response = self.handle_exception(e)
               ^^^^^^^^^^^^^^^^^^^^^^^^
  File "C:\Users\shrad\.virtualenvs\First_Flask-Zylcdab4\Lib\site-packages\flask\app.py", line 2525, in wsgi_app
    response = self.full_dispatch_request()
               ^^^^^^^^^^^^^^^^^^^^^^^^^^^^
  File "C:\Users\shrad\.virtualenvs\First_Flask-Zylcdab4\Lib\site-packages\flask\app.py", line 1822, in full_dispatch_request
    rv = self.handle_user_exception(e)
         ^^^^^^^^^^^^^^^^^^^^^^^^^^^^^
  File "C:\Users\shrad\.virtualenvs\First_Flask-Zylcdab4\Lib\site-packages\flask\app.py", line 1820, in full_dispatch_request
    rv = self.dispatch_request()
         ^^^^^^^^^^^^^^^^^^^^^^^
  File "C:\Users\shrad\.virtualenvs\First_Flask-Zylcdab4\Lib\site-packages\flask\app.py", line 1796, in dispatch_request
    return self.ensure_sync(self.view_functions[rule.endpoint])(**view_args)
           ^^^^^^^^^^^^^^^^^^^^^^^^^^^^^^^^^^^^^^^^^^^^^^^^^^^^^^^^^^^^^^^^^
  File "E:\Dojo\Pre-Bootcamp_Public\Pre-Bootcamp_Assignments\python\flask_mysql\db_connection\First_Flask\server.py", line 8, in index
    friends = Friend.get_all()
              ^^^^^^^^^^^^^^^^
  File "E:\Dojo\Pre-Bootcamp_Public\Pre-Bootcamp_Assignments\python\flask_mysql\db_connection\First_Flask\friend.py", line 19, in get_all
    results = connectToMySQL ('First_Flask').query_db(query)
              ^^^^^^^^^^^^^^^^^^^^^^^^^^^^^^^^^^^^^^^^^^^^^^
  File "E:\Dojo\Pre-Bootcamp_Public\Pre-Bootcamp_Assignments\python\flask_mysql\db_connection\First_Flask\mysqlconnection.py", line 48, in connectToMySQL
    return MySQLConnection(db)
           ^^^^^^^^^^^^^^^^^^^
  File "E:\Dojo\Pre-Bootcamp_Public\Pre-Bootcamp_Assignments\python\flask_mysql\db_connection\First_Flask\mysqlconnection.py", line 8, in __init__
    connection = pymysql.connect(host = "localhost",
                 ^^^^^^^^^^^^^^^^^^^^^^^^^^^^^^^^^^^
  File "C:\Users\shrad\.virtualenvs\First_Flask-Zylcdab4\Lib\site-packages\pymysql\connections.py", line 353, in __init__
    self.connect()
  File "C:\Users\shrad\.virtualenvs\First_Flask-Zylcdab4\Lib\site-packages\pymysql\connections.py", line 633, in connect
    self._request_authentication()
  File "C:\Users\shrad\.virtualenvs\First_Flask-Zylcdab4\Lib\site-packages\pymysql\connections.py", line 921, in _request_authentication
    auth_packet = self._process_auth(plugin_name, auth_packet)
                  ^^^^^^^^^^^^^^^^^^^^^^^^^^^^^^^^^^^^^^^^^^^^
  File "C:\Users\shrad\.virtualenvs\First_Flask-Zylcdab4\Lib\site-packages\pymysql\connections.py", line 1018, in _process_auth
    pkt = self._read_packet()
          ^^^^^^^^^^^^^^^^^^^
  File "C:\Users\shrad\.virtualenvs\First_Flask-Zylcdab4\Lib\site-packages\pymysql\connections.py", line 725, in _read_packet
    packet.raise_for_error()
  File "C:\Users\shrad\.virtualenvs\First_Flask-Zylcdab4\Lib\site-packages\pymysql\protocol.py", line 221, in raise_for_error
    err.raise_mysql_exception(self._data)
  File "C:\Users\shrad\.virtualenvs\First_Flask-Zylcdab4\Lib\site-packages\pymysql\err.py", line 143, in raise_mysql_exception
    raise errorclass(errno, errval)
pymysql.err.OperationalError: (1045, "Access denied for user 'root'@'localhost' (using password: YES)")
127.0.0.1 - - [09/Feb/2023 07:43:18] "GET /?__debugger__=yes&cmd=resource&f=style.css HTTP/1.1" 304 -
127.0.0.1 - - [09/Feb/2023 07:43:18] "GET /?__debugger__=yes&cmd=resource&f=debugger.js HTTP/1.1" 304 -
127.0.0.1 - - [09/Feb/2023 07:43:19] "GET /?__debugger__=yes&cmd=resource&f=console.png HTTP/1.1" 304 -
127.0.0.1 - - [09/Feb/2023 07:43:19] "GET /?__debugger__=yes&cmd=resource&f=console.png HTTP/1.1" 304 -